Traceback (most recent call last):
  File "/root/django_network_automation/venv/lib/python3.8/site-packages/paramiko/transport.py", line 2270, in _check_banner
    buf = self.packetizer.readline(timeout)
  File "/root/django_network_automation/venv/lib/python3.8/site-packages/paramiko/packet.py", line 374, in readline
    buf += self._read_timeout(timeout)
  File "/root/django_network_automation/venv/lib/python3.8/site-packages/paramiko/packet.py", line 601, in _read_timeout
    x = self.__socket.recv(128)
ConnectionResetError: [Errno 104] Connection reset by peer

During handling of the above exception, another exception occurred:

Traceback (most recent call last):
  File "/root/django_network_automation/venv/lib/python3.8/site-packages/netmiko/base_connection.py", line 1046, in establish_connection
    self.remote_conn_pre.connect(**ssh_connect_params)
  File "/root/django_network_automation/venv/lib/python3.8/site-packages/paramiko/client.py", line 430, in connect
    t.start_client(timeout=timeout)
  File "/root/django_network_automation/venv/lib/python3.8/site-packages/paramiko/transport.py", line 704, in start_client
    raise e
  File "/root/django_network_automation/venv/lib/python3.8/site-packages/paramiko/transport.py", line 2093, in run
    self._check_banner()
  File "/root/django_network_automation/venv/lib/python3.8/site-packages/paramiko/transport.py", line 2274, in _check_banner
    raise SSHException(
paramiko.ssh_exception.SSHException: Error reading SSH protocol banner[Errno 104] Connection reset by peer

During handling of the above exception, another exception occurred:

Traceback (most recent call last):
  File "/root/django_network_automation/venv/lib/python3.8/site-packages/nornir/core/task.py", line 99, in start
    r = self.task(self, **self.params)
  File "/root/django_network_automation/venv/lib/python3.8/site-packages/nornir_netmiko/tasks/netmiko_send_command.py", line 26, in netmiko_send_command
    net_connect = task.host.get_connection(CONNECTION_NAME, task.nornir.config)
  File "/root/django_network_automation/venv/lib/python3.8/site-packages/nornir/core/inventory.py", line 494, in get_connection
    self.open_connection(
  File "/root/django_network_automation/venv/lib/python3.8/site-packages/nornir/core/inventory.py", line 546, in open_connection
    conn_obj.open(
  File "/root/django_network_automation/venv/lib/python3.8/site-packages/nornir_netmiko/connections/netmiko.py", line 59, in open
    connection = ConnectHandler(**parameters)
  File "/root/django_network_automation/venv/lib/python3.8/site-packages/netmiko/ssh_dispatcher.py", line 365, in ConnectHandler
    return ConnectionClass(*args, **kwargs)
  File "/root/django_network_automation/venv/lib/python3.8/site-packages/netmiko/base_connection.py", line 439, in __init__
    self._open()
  File "/root/django_network_automation/venv/lib/python3.8/site-packages/netmiko/base_connection.py", line 444, in _open
    self.establish_connection()
  File "/root/django_network_automation/venv/lib/python3.8/site-packages/netmiko/base_connection.py", line 1099, in establish_connection
    raise NetmikoTimeoutException(msg)
netmiko.exceptions.NetmikoTimeoutException: 
A paramiko SSHException occurred during connection creation:

Error reading SSH protocol banner[Errno 104] Connection reset by peer


